[2025-10-02T18:16:43.789+0000] {taskinstance.py:1157} INFO - Dependencies all met for dep_context=non-requeueable deps ti=<TaskInstance: flujo_RAG.pinecone_upsert manual__2025-10-02T18:15:07+00:00 [queued]>
[2025-10-02T18:16:43.793+0000] {taskinstance.py:1157} INFO - Dependencies all met for dep_context=requeueable deps ti=<TaskInstance: flujo_RAG.pinecone_upsert manual__2025-10-02T18:15:07+00:00 [queued]>
[2025-10-02T18:16:43.794+0000] {taskinstance.py:1359} INFO - Starting attempt 1 of 1
[2025-10-02T18:16:43.799+0000] {taskinstance.py:1380} INFO - Executing <Task(PythonOperator): pinecone_upsert> on 2025-10-02 18:15:07+00:00
[2025-10-02T18:16:43.803+0000] {standard_task_runner.py:57} INFO - Started process 62656 to run task
[2025-10-02T18:16:43.806+0000] {standard_task_runner.py:84} INFO - Running: ['***', 'tasks', 'run', 'flujo_RAG', 'pinecone_upsert', 'manual__2025-10-02T18:15:07+00:00', '--job-id', '150', '--raw', '--subdir', 'DAGS_FOLDER/RAG_dag.py', '--cfg-path', '/tmp/tmphq23is1n']
[2025-10-02T18:16:43.808+0000] {standard_task_runner.py:85} INFO - Job 150: Subtask pinecone_upsert
[2025-10-02T18:16:43.831+0000] {task_command.py:415} INFO - Running <TaskInstance: flujo_RAG.pinecone_upsert manual__2025-10-02T18:15:07+00:00 [running]> on host cebfb690f74d
[2025-10-02T18:16:43.869+0000] {taskinstance.py:1660} INFO - Exporting env vars: AIRFLOW_CTX_DAG_OWNER='***' AIRFLOW_CTX_DAG_ID='flujo_RAG' AIRFLOW_CTX_TASK_ID='pinecone_upsert' AIRFLOW_CTX_EXECUTION_DATE='2025-10-02T18:15:07+00:00' AIRFLOW_CTX_TRY_NUMBER='1' AIRFLOW_CTX_DAG_RUN_ID='manual__2025-10-02T18:15:07+00:00'
[2025-10-02T18:16:43.870+0000] {taskinstance.py:1935} ERROR - Task failed with exception
Traceback (most recent call last):
  File "/home/airflow/.local/lib/python3.8/site-packages/airflow/operators/python.py", line 192, in execute
    return_value = self.execute_callable()
  File "/home/airflow/.local/lib/python3.8/site-packages/airflow/operators/python.py", line 209, in execute_callable
    return self.python_callable(*self.op_args, **self.op_kwargs)
  File "/opt/airflow/plugins/tasks/pinecone_upsert_task.py", line 15, in task_pinecone_upsert
    out = upsert_vectors_from_ndjson(
TypeError: upsert_vectors_from_ndjson() got an unexpected keyword argument 'bucket'
[2025-10-02T18:16:43.875+0000] {taskinstance.py:1398} INFO - Marking task as FAILED. dag_id=flujo_RAG, task_id=pinecone_upsert, execution_date=20251002T181507, start_date=20251002T181643, end_date=20251002T181643
[2025-10-02T18:16:43.880+0000] {standard_task_runner.py:104} ERROR - Failed to execute job 150 for task pinecone_upsert (upsert_vectors_from_ndjson() got an unexpected keyword argument 'bucket'; 62656)
[2025-10-02T18:16:43.898+0000] {local_task_job_runner.py:228} INFO - Task exited with return code 1
[2025-10-02T18:16:43.911+0000] {taskinstance.py:2776} INFO - 0 downstream tasks scheduled from follow-on schedule check
