[2025-09-30T14:36:52.083+0000] {taskinstance.py:1157} INFO - Dependencies all met for dep_context=non-requeueable deps ti=<TaskInstance: flujo_RAG.procesar_dataset_minio manual__2025-09-30T14:36:49.523316+00:00 [queued]>
[2025-09-30T14:36:52.089+0000] {taskinstance.py:1157} INFO - Dependencies all met for dep_context=requeueable deps ti=<TaskInstance: flujo_RAG.procesar_dataset_minio manual__2025-09-30T14:36:49.523316+00:00 [queued]>
[2025-09-30T14:36:52.089+0000] {taskinstance.py:1359} INFO - Starting attempt 1 of 1
[2025-09-30T14:36:52.094+0000] {taskinstance.py:1380} INFO - Executing <Task(PythonOperator): procesar_dataset_minio> on 2025-09-30 14:36:49.523316+00:00
[2025-09-30T14:36:52.099+0000] {standard_task_runner.py:57} INFO - Started process 170 to run task
[2025-09-30T14:36:52.101+0000] {standard_task_runner.py:84} INFO - Running: ['***', 'tasks', 'run', 'flujo_RAG', 'procesar_dataset_minio', 'manual__2025-09-30T14:36:49.523316+00:00', '--job-id', '3', '--raw', '--subdir', 'DAGS_FOLDER/RAG_dag.py', '--cfg-path', '/tmp/tmpmgmvb9nj']
[2025-09-30T14:36:52.103+0000] {standard_task_runner.py:85} INFO - Job 3: Subtask procesar_dataset_minio
[2025-09-30T14:36:52.130+0000] {task_command.py:415} INFO - Running <TaskInstance: flujo_RAG.procesar_dataset_minio manual__2025-09-30T14:36:49.523316+00:00 [running]> on host 536168cd08ce
[2025-09-30T14:36:52.166+0000] {taskinstance.py:1660} INFO - Exporting env vars: AIRFLOW_CTX_DAG_OWNER='***' AIRFLOW_CTX_DAG_ID='flujo_RAG' AIRFLOW_CTX_TASK_ID='procesar_dataset_minio' AIRFLOW_CTX_EXECUTION_DATE='2025-09-30T14:36:49.523316+00:00' AIRFLOW_CTX_TRY_NUMBER='1' AIRFLOW_CTX_DAG_RUN_ID='manual__2025-09-30T14:36:49.523316+00:00'
[2025-09-30T14:36:52.167+0000] {crypto.py:82} WARNING - empty cryptography key - values will not be stored encrypted.
[2025-09-30T14:36:52.168+0000] {base.py:73} INFO - Using connection ID 'minio_s3' for task execution.
[2025-09-30T14:36:52.168+0000] {warnings.py:109} WARNING - <string>:8: AirflowProviderDeprecationWarning: AWS Connection (conn_id='minio_s3', conn_type='s3') has connection type 's3', which has been replaced by connection type 'aws'. Please update your connection to have `conn_type='aws'`.

[2025-09-30T14:36:52.169+0000] {connection_wrapper.py:340} INFO - AWS Connection (conn_id='minio_s3', conn_type='s3') credentials retrieved from login and password.
[2025-09-30T14:36:52.169+0000] {warnings.py:109} WARNING - <string>:8: AirflowProviderDeprecationWarning: Host minio specified in the connection is not used. Please, set it on extra['endpoint_url'] instead

[2025-09-30T14:36:52.449+0000] {taskinstance.py:1935} ERROR - Task failed with exception
Traceback (most recent call last):
  File "/home/airflow/.local/lib/python3.8/site-packages/airflow/operators/python.py", line 192, in execute
    return_value = self.execute_callable()
  File "/home/airflow/.local/lib/python3.8/site-packages/airflow/operators/python.py", line 209, in execute_callable
    return self.python_callable(*self.op_args, **self.op_kwargs)
  File "/opt/airflow/plugins/tasks/procesamiento_utils.py", line 43, in leer_y_loguear_minio
    file_content = hook.read_key(key=input_key, bucket_name=bucket_name)
  File "/home/airflow/.local/lib/python3.8/site-packages/airflow/providers/amazon/aws/hooks/s3.py", line 138, in wrapper
    return func(*bound_args.args, **bound_args.kwargs)
  File "/home/airflow/.local/lib/python3.8/site-packages/airflow/providers/amazon/aws/hooks/s3.py", line 92, in wrapper
    return func(*bound_args.args, **bound_args.kwargs)
  File "/home/airflow/.local/lib/python3.8/site-packages/airflow/providers/amazon/aws/hooks/s3.py", line 940, in read_key
    obj = self.get_key(key, bucket_name)
  File "/home/airflow/.local/lib/python3.8/site-packages/airflow/providers/amazon/aws/hooks/s3.py", line 138, in wrapper
    return func(*bound_args.args, **bound_args.kwargs)
  File "/home/airflow/.local/lib/python3.8/site-packages/airflow/providers/amazon/aws/hooks/s3.py", line 92, in wrapper
    return func(*bound_args.args, **bound_args.kwargs)
  File "/home/airflow/.local/lib/python3.8/site-packages/airflow/providers/amazon/aws/hooks/s3.py", line 924, in get_key
    obj.load()
  File "/home/airflow/.local/lib/python3.8/site-packages/boto3/resources/factory.py", line 564, in do_action
    response = action(self, *args, **kwargs)
  File "/home/airflow/.local/lib/python3.8/site-packages/boto3/resources/action.py", line 88, in __call__
    response = getattr(parent.meta.client, operation_name)(*args, **params)
  File "/home/airflow/.local/lib/python3.8/site-packages/botocore/client.py", line 535, in _api_call
    return self._make_api_call(operation_name, kwargs)
  File "/home/airflow/.local/lib/python3.8/site-packages/botocore/client.py", line 980, in _make_api_call
    raise error_class(parsed_response, operation_name)
botocore.exceptions.ClientError: An error occurred (404) when calling the HeadObject operation: Not Found
[2025-09-30T14:36:52.455+0000] {taskinstance.py:1398} INFO - Marking task as FAILED. dag_id=flujo_RAG, task_id=procesar_dataset_minio, execution_date=20250930T143649, start_date=20250930T143652, end_date=20250930T143652
[2025-09-30T14:36:52.495+0000] {standard_task_runner.py:104} ERROR - Failed to execute job 3 for task procesar_dataset_minio (An error occurred (404) when calling the HeadObject operation: Not Found; 170)
[2025-09-30T14:36:52.516+0000] {local_task_job_runner.py:228} INFO - Task exited with return code 1
[2025-09-30T14:36:52.526+0000] {taskinstance.py:2776} INFO - 0 downstream tasks scheduled from follow-on schedule check
