[2025-10-07T10:48:13.012+0000] {taskinstance.py:1157} INFO - Dependencies all met for dep_context=non-requeueable deps ti=<TaskInstance: flujo_RAG_completo.classify_op_texts manual__2025-10-07T02:26:17+00:00 [queued]>
[2025-10-07T10:48:13.016+0000] {taskinstance.py:1157} INFO - Dependencies all met for dep_context=requeueable deps ti=<TaskInstance: flujo_RAG_completo.classify_op_texts manual__2025-10-07T02:26:17+00:00 [queued]>
[2025-10-07T10:48:13.017+0000] {taskinstance.py:1359} INFO - Starting attempt 5 of 5
[2025-10-07T10:48:13.023+0000] {taskinstance.py:1380} INFO - Executing <Task(PythonOperator): classify_op_texts> on 2025-10-07 02:26:17+00:00
[2025-10-07T10:48:13.030+0000] {standard_task_runner.py:57} INFO - Started process 11363 to run task
[2025-10-07T10:48:13.033+0000] {standard_task_runner.py:84} INFO - Running: ['***', 'tasks', 'run', 'flujo_RAG_completo', 'classify_op_texts', 'manual__2025-10-07T02:26:17+00:00', '--job-id', '314', '--raw', '--subdir', 'DAGS_FOLDER/Ingestion_pipeline.py', '--cfg-path', '/tmp/tmp6dvy51th']
[2025-10-07T10:48:13.035+0000] {standard_task_runner.py:85} INFO - Job 314: Subtask classify_op_texts
[2025-10-07T10:48:13.059+0000] {task_command.py:415} INFO - Running <TaskInstance: flujo_RAG_completo.classify_op_texts manual__2025-10-07T02:26:17+00:00 [running]> on host a21c1baf7ef9
[2025-10-07T10:48:13.096+0000] {taskinstance.py:1660} INFO - Exporting env vars: AIRFLOW_CTX_DAG_OWNER='***' AIRFLOW_CTX_DAG_ID='flujo_RAG_completo' AIRFLOW_CTX_TASK_ID='classify_op_texts' AIRFLOW_CTX_EXECUTION_DATE='2025-10-07T02:26:17+00:00' AIRFLOW_CTX_TRY_NUMBER='5' AIRFLOW_CTX_DAG_RUN_ID='manual__2025-10-07T02:26:17+00:00'
[2025-10-07T10:48:13.176+0000] {taskinstance.py:1935} ERROR - Task failed with exception
Traceback (most recent call last):
  File "/home/airflow/.local/lib/python3.8/site-packages/airflow/operators/python.py", line 192, in execute
    return_value = self.execute_callable()
  File "/home/airflow/.local/lib/python3.8/site-packages/airflow/operators/python.py", line 209, in execute_callable
    return self.python_callable(*self.op_args, **self.op_kwargs)
  File "/opt/airflow/plugins/tasks/classify_op_texts_task.py", line 543, in task_classify_op_texts
    raise FileNotFoundError(
FileNotFoundError: No se encontraron sidecars en s3://respaldo2/rag/text_op_meta/2025/docs/ (asegurate de haber corrido la tarea de extracci贸n que gener贸 metadatos)
[2025-10-07T10:48:13.183+0000] {taskinstance.py:1398} INFO - Marking task as FAILED. dag_id=flujo_RAG_completo, task_id=classify_op_texts, execution_date=20251007T022617, start_date=20251007T104813, end_date=20251007T104813
[2025-10-07T10:48:13.188+0000] {standard_task_runner.py:104} ERROR - Failed to execute job 314 for task classify_op_texts (No se encontraron sidecars en s3://respaldo2/rag/text_op_meta/2025/docs/ (asegurate de haber corrido la tarea de extracci贸n que gener贸 metadatos); 11363)
[2025-10-07T10:48:13.214+0000] {local_task_job_runner.py:228} INFO - Task exited with return code 1
[2025-10-07T10:48:13.224+0000] {taskinstance.py:2776} INFO - 0 downstream tasks scheduled from follow-on schedule check
